{"timestamp": "2025-08-25T09:53:19.211325", "context": "failing_function", "error_type": "MemoryError", "error_message": "Out of memory", "traceback": "Traceback (most recent call last):\n  File \"C:\\Users\\Acer\\risk-model-pipeline\\src\\risk_pipeline\\utils\\error_handler.py\", line 39, in safe_execute\n    return func(*args, **kwargs)\n  File \"C:\\Users\\Acer\\risk-model-pipeline\\tests\\test_error_handler.py\", line 37, in failing_function\n    raise MemoryError(\"Out of memory\")\nMemoryError: Out of memory\n"}
{"timestamp": "2025-08-25T09:53:19.214326", "context": "failing_function", "error_type": "ValueError", "error_message": "Invalid value", "traceback": "Traceback (most recent call last):\n  File \"C:\\Users\\Acer\\risk-model-pipeline\\src\\risk_pipeline\\utils\\error_handler.py\", line 39, in safe_execute\n    return func(*args, **kwargs)\n  File \"C:\\Users\\Acer\\risk-model-pipeline\\tests\\test_error_handler.py\", line 51, in failing_function\n    raise ValueError(\"Invalid value\")\nValueError: Invalid value\n"}
{"timestamp": "2025-08-25T10:05:38.875729", "context": "failing_function", "error_type": "MemoryError", "error_message": "Out of memory", "traceback": "Traceback (most recent call last):\n  File \"C:\\Users\\Acer\\risk-model-pipeline\\src\\risk_pipeline\\utils\\error_handler.py\", line 39, in safe_execute\n    return func(*args, **kwargs)\n  File \"C:\\Users\\Acer\\risk-model-pipeline\\tests\\test_error_handler.py\", line 37, in failing_function\n    raise MemoryError(\"Out of memory\")\nMemoryError: Out of memory\n"}
{"timestamp": "2025-08-25T10:05:38.877688", "context": "failing_function", "error_type": "ValueError", "error_message": "Invalid value", "traceback": "Traceback (most recent call last):\n  File \"C:\\Users\\Acer\\risk-model-pipeline\\src\\risk_pipeline\\utils\\error_handler.py\", line 39, in safe_execute\n    return func(*args, **kwargs)\n  File \"C:\\Users\\Acer\\risk-model-pipeline\\tests\\test_error_handler.py\", line 51, in failing_function\n    raise ValueError(\"Invalid value\")\nValueError: Invalid value\n"}
